<?xml version="1.0" ?>
<robot name="bal_robot_urdf" xmlns:xacro="http://www.ros.org/wiki/xacro">

<xacro:include filename="$(find bal_robot_urdf_description)/urdf/materials.xacro" />
<xacro:include filename="$(find bal_robot_urdf_description)/urdf/bal_robot_urdf.trans" />
<xacro:include filename="$(find bal_robot_urdf_description)/urdf/bal_robot_urdf.gazebo" />
<xacro:include filename="$(find bal_robot_urdf_description)/urdf/plugins_urdf.gazebo" />
<xacro:include filename="$(find bal_robot_urdf_description)/urdf/gazebo_control.xacro" />
<link name="base_link">
  <inertial>
    <origin xyz="0.037767664605411484 0.0012253431896488407 0.08327847794759455" rpy="0 0 0"/>
    <mass value="6.667201834536198"/>
    <inertia ixx="0.028451" iyy="0.056744" izz="0.071354" ixy="-0.0" iyz="0.0" ixz="-0.001806"/>
  </inertial>
  <visual>
    <origin xyz="0 0 0" rpy="0 0 0"/>
    <geometry>
      <mesh filename="file://$(find bal_robot_urdf_description)/meshes/base_link.stl" scale="0.001 0.001 0.001"/>
    </geometry>
    <material name="silver"/>
  </visual>
  <collision>
    <origin xyz="0 0 0" rpy="0 0 0"/>
    <geometry>
      <mesh filename="file://$(find bal_robot_urdf_description)/meshes/base_link.stl" scale="0.001 0.001 0.001"/>
    </geometry>
  </collision>
</link>

<link name="lidar_1">
  <inertial>
    <origin xyz="1.44853377330445e-06 2.7616170642256674e-07 0.010000470080404444" rpy="0 0 0"/>
    <mass value="0.6042382071025928"/>
    <inertia ixx="0.000205" iyy="0.000205" izz="0.00037" ixy="-0.0" iyz="-0.0" ixz="-0.0"/>
  </inertial>
  <visual>
    <origin xyz="-0.117737 -0.001226 -0.164764" rpy="0 0 0"/>
    <geometry>
      <mesh filename="file://$(find bal_robot_urdf_description)/meshes/lidar_1.stl" scale="0.001 0.001 0.001"/>
    </geometry>
    <material name="silver"/>
  </visual>
  <collision>
    <origin xyz="-0.117737 -0.001226 -0.164764" rpy="0 0 0"/>
    <geometry>
      <mesh filename="file://$(find bal_robot_urdf_description)/meshes/lidar_1.stl" scale="0.001 0.001 0.001"/>
    </geometry>
  </collision>
</link>

<link name="realsence_1">
  <inertial>
    <origin xyz="0.004999707663906422 2.761617057150164e-07 -1.0024462618329899e-07" rpy="0 0 0"/>
    <mass value="0.08242500245645643"/>
    <inertia ixx="3.5e-05" iyy="2e-06" izz="3.4e-05" ixy="-0.0" iyz="-0.0" ixz="0.0"/>
  </inertial>
  <visual>
    <origin xyz="-0.187737 -0.001226 -0.082264" rpy="0 0 0"/>
    <geometry>
      <mesh filename="file://$(find bal_robot_urdf_description)/meshes/realsence_1.stl" scale="0.001 0.001 0.001"/>
    </geometry>
    <material name="silver"/>
  </visual>
  <collision>
    <origin xyz="-0.187737 -0.001226 -0.082264" rpy="0 0 0"/>
    <geometry>
      <mesh filename="file://$(find bal_robot_urdf_description)/meshes/realsence_1.stl" scale="0.001 0.001 0.001"/>
    </geometry>
  </collision>
</link>

<link name="rfwheel_1">
  <inertial>
    <origin xyz="-0.0004889140025854805 -0.014999723838293719 0.00011426195402471084" rpy="0 0 0"/>
    <mass value="2.044817023447539"/>
    <inertia ixx="0.001605" iyy="0.002914" izz="0.001615" ixy="-0.0" iyz="-0.0" ixz="2e-06"/>
  </inertial>
  <visual>
    <origin xyz="-0.107737 0.108774 -0.054764" rpy="0 0 0"/>
    <geometry>
      <mesh filename="file://$(find bal_robot_urdf_description)/meshes/rfwheel_1.stl" scale="0.001 0.001 0.001"/>
    </geometry>
    <material name="silver"/>
  </visual>
  <collision>
    <origin xyz="-0.107737 0.108774 -0.054764" rpy="0 0 0"/>
    <geometry>
      <mesh filename="file://$(find bal_robot_urdf_description)/meshes/rfwheel_1.stl" scale="0.001 0.001 0.001"/>
    </geometry>
  </collision>
</link>

<link name="rbwheel_1">
  <inertial>
    <origin xyz="-0.0004889140025840233 -0.014999723838292706 0.00011426195402416961" rpy="0 0 0"/>
    <mass value="2.0448170234475396"/>
    <inertia ixx="0.001605" iyy="0.002914" izz="0.001615" ixy="0.0" iyz="-0.0" ixz="2e-06"/>
  </inertial>
  <visual>
    <origin xyz="0.042263 0.108774 -0.054764" rpy="0 0 0"/>
    <geometry>
      <mesh filename="file://$(find bal_robot_urdf_description)/meshes/rbwheel_1.stl" scale="0.001 0.001 0.001"/>
    </geometry>
    <material name="silver"/>
  </visual>
  <collision>
    <origin xyz="0.042263 0.108774 -0.054764" rpy="0 0 0"/>
    <geometry>
      <mesh filename="file://$(find bal_robot_urdf_description)/meshes/rbwheel_1.stl" scale="0.001 0.001 0.001"/>
    </geometry>
  </collision>
</link>

<link name="lfwheel_1">
  <inertial>
    <origin xyz="-0.0004889140025847172 0.01500027616170617 0.00011426195402349654" rpy="0 0 0"/>
    <mass value="2.044817023447539"/>
    <inertia ixx="0.001605" iyy="0.002914" izz="0.001615" ixy="0.0" iyz="-0.0" ixz="2e-06"/>
  </inertial>
  <visual>
    <origin xyz="-0.107737 -0.111226 -0.054764" rpy="0 0 0"/>
    <geometry>
      <mesh filename="file://$(find bal_robot_urdf_description)/meshes/lfwheel_1.stl" scale="0.001 0.001 0.001"/>
    </geometry>
    <material name="silver"/>
  </visual>
  <collision>
    <origin xyz="-0.107737 -0.111226 -0.054764" rpy="0 0 0"/>
    <geometry>
      <mesh filename="file://$(find bal_robot_urdf_description)/meshes/lfwheel_1.stl" scale="0.001 0.001 0.001"/>
    </geometry>
  </collision>
</link>

<link name="lbwheel_1">
  <inertial>
    <origin xyz="-0.0004889140025833849 0.015000276161707196 0.00011426195402289979" rpy="0 0 0"/>
    <mass value="2.0448170234475396"/>
    <inertia ixx="0.001605" iyy="0.002914" izz="0.001615" ixy="0.0" iyz="-0.0" ixz="2e-06"/>
  </inertial>
  <visual>
    <origin xyz="0.042263 -0.111226 -0.054764" rpy="0 0 0"/>
    <geometry>
      <mesh filename="file://$(find bal_robot_urdf_description)/meshes/lbwheel_1.stl" scale="0.001 0.001 0.001"/>
    </geometry>
    <material name="silver"/>
  </visual>
  <collision>
    <origin xyz="0.042263 -0.111226 -0.054764" rpy="0 0 0"/>
    <geometry>
      <mesh filename="file://$(find bal_robot_urdf_description)/meshes/lbwheel_1.stl" scale="0.001 0.001 0.001"/>
    </geometry>
  </collision>
</link>

<link name="imu_1">
  <inertial>
    <origin xyz="8.556984261789968e-10 2.420403805189785e-12 0.004999898451521614" rpy="0 0 0"/>
    <mass value="0.06280000187158614"/>
    <inertia ixx="3e-06" iyy="9e-06" izz="1e-05" ixy="0.0" iyz="-0.0" ixz="-0.0"/>
  </inertial>
  <visual>
    <origin xyz="0.005 -0.0 -0.099764" rpy="0 0 0"/>
    <geometry>
      <mesh filename="file://$(find bal_robot_urdf_description)/meshes/imu_1.stl" scale="0.001 0.001 0.001"/>
    </geometry>
    <material name="silver"/>
  </visual>
  <collision>
    <origin xyz="0.005 -0.0 -0.099764" rpy="0 0 0"/>
    <geometry>
      <mesh filename="file://$(find bal_robot_urdf_description)/meshes/imu_1.stl" scale="0.001 0.001 0.001"/>
    </geometry>
  </collision>
</link>

<link name="gps_1">
  <inertial>
    <origin xyz="9.296814013071142e-10 2.4204614829476862e-12 0.0024998984515221534" rpy="0 0 0"/>
    <mass value="0.003082687791335116"/>
    <inertia ixx="0.0" iyy="0.0" izz="0.0" ixy="0.0" iyz="-0.0" ixz="-0.0"/>
  </inertial>
  <visual>
    <origin xyz="0.075 -0.0 -0.139764" rpy="0 0 0"/>
    <geometry>
      <mesh filename="file://$(find bal_robot_urdf_description)/meshes/gps_1.stl" scale="0.001 0.001 0.001"/>
    </geometry>
    <material name="silver"/>
  </visual>
  <collision>
    <origin xyz="0.075 -0.0 -0.139764" rpy="0 0 0"/>
    <geometry>
      <mesh filename="file://$(find bal_robot_urdf_description)/meshes/gps_1.stl" scale="0.001 0.001 0.001"/>
    </geometry>
  </collision>
</link>

<joint name="Rigid 2" type="fixed">
  <origin xyz="0.117737 0.001226 0.164764" rpy="0 0 0"/>
  <parent link="base_link"/>
  <child link="lidar_1"/>
</joint>

<joint name="Rigid 3" type="fixed">
  <origin xyz="0.187737 0.001226 0.082264" rpy="0 0 0"/>
  <parent link="base_link"/>
  <child link="realsence_1"/>
</joint>

<joint name="Revolute 4" type="continuous">
  <origin xyz="0.107737 -0.108774 0.054764" rpy="0 0 0"/>
  <parent link="base_link"/>
  <child link="rfwheel_1"/>
  <axis xyz="-0.0 1.0 -0.0"/>
</joint>

<joint name="Revolute 5" type="continuous">
  <origin xyz="-0.042263 -0.108774 0.054764" rpy="0 0 0"/>
  <parent link="base_link"/>
  <child link="rbwheel_1"/>
  <axis xyz="-0.0 1.0 -0.0"/>
</joint>

<joint name="Revolute 6" type="continuous">
  <origin xyz="0.107737 0.111226 0.054764" rpy="0 0 0"/>
  <parent link="base_link"/>
  <child link="lfwheel_1"/>
  <axis xyz="0.0 1.0 -0.0"/>
</joint>

<joint name="Revolute 7" type="continuous">
  <origin xyz="-0.042263 0.111226 0.054764" rpy="0 0 0"/>
  <parent link="base_link"/>
  <child link="lbwheel_1"/>
  <axis xyz="0.0 1.0 -0.0"/>
</joint>

<joint name="Rigid 9" type="fixed">
  <origin xyz="-0.005 0.0 0.099764" rpy="0 0 0"/>
  <parent link="base_link"/>
  <child link="imu_1"/>
</joint>

<joint name="Rigid 10" type="fixed">
  <origin xyz="-0.075 0.0 0.139764" rpy="0 0 0"/>
  <parent link="base_link"/>
  <child link="gps_1"/>
</joint>

<joint name="base_footprint_joint" type="fixed">
  <origin xyz="0 0 0" rpy="0 0 0"/>
  <parent link="base_link"/>
  <child link="base_footprint"/>
</joint>

<link name="base_footprint">
</link>

</robot>
