<sdf version='1.7'>
  <world name='default'>
    <light name='sun' type='directional'>
      <cast_shadows>1</cast_shadows>
      <pose>0 0 10 0 -0 0</pose>
      <diffuse>0.8 0.8 0.8 1</diffuse>
      <specular>0.2 0.2 0.2 1</specular>
      <attenuation>
        <range>1000</range>
        <constant>0.9</constant>
        <linear>0.01</linear>
        <quadratic>0.001</quadratic>
      </attenuation>
      <direction>-0.5 0.1 -0.9</direction>
      <spot>
        <inner_angle>0</inner_angle>
        <outer_angle>0</outer_angle>
        <falloff>0</falloff>
      </spot>
    </light>
    <model name='ground_plane'>
      <static>1</static>
      <link name='link'>
        <collision name='collision'>
          <geometry>
            <plane>
              <normal>0 0 1</normal>
              <size>100 100</size>
            </plane>
          </geometry>
          <surface>
            <friction>
              <ode>
                <mu>100</mu>
                <mu2>50</mu2>
              </ode>
              <torsional>
                <ode/>
              </torsional>
            </friction>
            <contact>
              <ode/>
            </contact>
            <bounce/>
          </surface>
          <max_contacts>10</max_contacts>
        </collision>
        <visual name='visual'>
          <cast_shadows>0</cast_shadows>
          <geometry>
            <plane>
              <normal>0 0 1</normal>
              <size>100 100</size>
            </plane>
          </geometry>
          <material>
            <script>
              <uri>file://media/materials/scripts/gazebo.material</uri>
              <name>Gazebo/Grey</name>
            </script>
          </material>
        </visual>
        <self_collide>0</self_collide>
        <enable_wind>0</enable_wind>
        <kinematic>0</kinematic>
      </link>
    </model>
    <gravity>0 0 -9.8</gravity>
    <magnetic_field>6e-06 2.3e-05 -4.2e-05</magnetic_field>
    <atmosphere type='adiabatic'/>
    <physics type='ode'>
      <max_step_size>0.001</max_step_size>
      <real_time_factor>1</real_time_factor>
      <real_time_update_rate>1000</real_time_update_rate>
    </physics>
    <scene>
      <ambient>0.4 0.4 0.4 1</ambient>
      <background>0.7 0.7 0.7 1</background>
      <shadows>1</shadows>
    </scene>
    <audio>
      <device>default</device>
    </audio>
    <wind/>
    <spherical_coordinates>
      <surface_model>EARTH_WGS84</surface_model>
      <latitude_deg>0</latitude_deg>
      <longitude_deg>0</longitude_deg>
      <elevation>0</elevation>
      <heading_deg>0</heading_deg>
    </spherical_coordinates>
    <model name='line_track'>
      <link name='link_0'>
        <inertial>
          <mass>1</mass>
          <inertia>
            <ixx>0.166667</ixx>
            <ixy>0</ixy>
            <ixz>0</ixz>
            <iyy>0.166667</iyy>
            <iyz>0</iyz>
            <izz>0.166667</izz>
          </inertia>
        </inertial>
        <pose>0.848639 -0.049037 0 0 -0 0</pose>
        <visual name='visual'>
          <pose>0 0 0 0 -0 0</pose>
          <geometry>
            <mesh>
              <uri>/home/luqman/robotisim_ws/src/robot_sensing/models/meshes/base.dae</uri>
              <scale>1 1 1</scale>
            </mesh>
          </geometry>
          <material>
            <lighting>1</lighting>
            <script>
              <uri>file://media/materials/scripts/gazebo.material</uri>
              <name>Gazebo/Grey</name>
            </script>
            <shader type='pixel'/>
            <emissive>0 0 0 1</emissive>
          </material>
          <transparency>0</transparency>
          <cast_shadows>1</cast_shadows>
        </visual>
        <collision name='collision'>
          <laser_retro>0</laser_retro>
          <max_contacts>10</max_contacts>
          <pose>0 0 0 0 -0 0</pose>
          <geometry>
            <mesh>
              <uri>/home/abcom/Documents/GitHub/assignment_ws/src/robotics_software_engineer/bal_robot_urdf_description/model/meshes/base.dae</uri>
              <scale>1 1 1</scale>
            </mesh>
          </geometry>
          <surface>
            <friction>
              <ode>
                <mu>1</mu>
                <mu2>1</mu2>
                <fdir1>0 0 0</fdir1>
                <slip1>0</slip1>
                <slip2>0</slip2>
              </ode>
              <torsional>
                <coefficient>1</coefficient>
                <patch_radius>0</patch_radius>
                <surface_radius>0</surface_radius>
                <use_patch_radius>1</use_patch_radius>
                <ode>
                  <slip>0</slip>
                </ode>
              </torsional>
            </friction>
            <bounce>
              <restitution_coefficient>0</restitution_coefficient>
              <threshold>1e+06</threshold>
            </bounce>
            <contact>
              <collide_without_contact>0</collide_without_contact>
              <collide_without_contact_bitmask>1</collide_without_contact_bitmask>
              <collide_bitmask>1</collide_bitmask>
              <ode>
                <soft_cfm>0</soft_cfm>
                <soft_erp>0.2</soft_erp>
                <kp>1e+13</kp>
                <kd>1</kd>
                <max_vel>0.01</max_vel>
                <min_depth>0</min_depth>
              </ode>
              <bullet>
                <split_impulse>1</split_impulse>
                <split_impulse_penetration_threshold>-0.01</split_impulse_penetration_threshold>
                <soft_cfm>0</soft_cfm>
                <soft_erp>0.2</soft_erp>
                <kp>1e+13</kp>
                <kd>1</kd>
              </bullet>
            </contact>
          </surface>
        </collision>
        <self_collide>0</self_collide>
        <enable_wind>0</enable_wind>
        <kinematic>0</kinematic>
      </link>
      <link name='link_1'>
        <inertial>
          <mass>1</mass>
          <inertia>
            <ixx>0.166667</ixx>
            <ixy>0</ixy>
            <ixz>0</ixz>
            <iyy>0.166667</iyy>
            <iyz>0</iyz>
            <izz>0.166667</izz>
          </inertia>
        </inertial>
        <pose>-0.848635 0.049036 0.001 0 -0 0</pose>
        <visual name='visual'>
          <pose>0 0 0 0 -0 0</pose>
          <geometry>
            <mesh>
              <uri>/home/abcom/Documents/GitHub/assignment_ws/src/robotics_software_engineer/bal_robot_urdf_description/model/meshes/line.dae</uri>
              <scale>1 1 1</scale>
            </mesh>
          </geometry>
          <material>
            <lighting>1</lighting>
            <script>
              <uri>file://media/materials/scripts/gazebo.material</uri>
              <name>Gazebo/Black</name>
            </script>
            <shader type='pixel'/>
            <emissive>0 0 0 1</emissive>
          </material>
          <transparency>0</transparency>
          <cast_shadows>1</cast_shadows>
        </visual>
        <collision name='collision'>
          <laser_retro>0</laser_retro>
          <max_contacts>10</max_contacts>
          <pose>0 0 0 0 -0 0</pose>
          <geometry>
            <mesh>
              <uri>/home/abcom/Documents/GitHub/assignment_ws/src/robotics_software_engineer/bal_robot_urdf_description/model/meshes/line.dae</uri>
              <scale>1 1 1</scale>
            </mesh>
          </geometry>
          <surface>
            <friction>
              <ode>
                <mu>1</mu>
                <mu2>1</mu2>
                <fdir1>0 0 0</fdir1>
                <slip1>0</slip1>
                <slip2>0</slip2>
              </ode>
              <torsional>
                <coefficient>1</coefficient>
                <patch_radius>0</patch_radius>
                <surface_radius>0</surface_radius>
                <use_patch_radius>1</use_patch_radius>
                <ode>
                  <slip>0</slip>
                </ode>
              </torsional>
            </friction>
            <bounce>
              <restitution_coefficient>0</restitution_coefficient>
              <threshold>1e+06</threshold>
            </bounce>
            <contact>
              <collide_without_contact>0</collide_without_contact>
              <collide_without_contact_bitmask>1</collide_without_contact_bitmask>
              <collide_bitmask>1</collide_bitmask>
              <ode>
                <soft_cfm>0</soft_cfm>
                <soft_erp>0.2</soft_erp>
                <kp>1e+13</kp>
                <kd>1</kd>
                <max_vel>0.01</max_vel>
                <min_depth>0</min_depth>
              </ode>
              <bullet>
                <split_impulse>1</split_impulse>
                <split_impulse_penetration_threshold>-0.01</split_impulse_penetration_threshold>
                <soft_cfm>0</soft_cfm>
                <soft_erp>0.2</soft_erp>
                <kp>1e+13</kp>
                <kd>1</kd>
              </bullet>
            </contact>
          </surface>
        </collision>
        <self_collide>0</self_collide>
        <enable_wind>0</enable_wind>
        <kinematic>0</kinematic>
      </link>
      <joint name='link_0_JOINT_0' type='fixed'>
        <parent>link_0</parent>
        <child>link_1</child>
        <pose>0 0 0 0 -0 0</pose>
        <physics>
          <ode>
            <limit>
              <cfm>0</cfm>
              <erp>0.2</erp>
            </limit>
            <suspension>
              <cfm>0</cfm>
              <erp>0.2</erp>
            </suspension>
          </ode>
        </physics>
      </joint>
      <static>1</static>
      <allow_auto_disable>1</allow_auto_disable>
      <pose>-2.86298 2.05919 0 0 -0 0</pose>
    </model>
    <state world_name='default'>
      <sim_time>378 649000000</sim_time>
      <real_time>485 268919869</real_time>
      <wall_time>1729255614 415200604</wall_time>
      <iterations>211104</iterations>
      <model name='bal_robot_urdf'>
        <pose>2.13437 -0.992813 0.034974 0.001237 0.001827 3.07594</pose>
        <scale>1 1 1</scale>
        <link name='base_link'>
          <pose>2.13437 -0.992813 0.034974 0.001237 0.001827 3.07594</pose>
          <velocity>-6.3e-05 -0.002989 -0.00086 -0.042505 0.006882 -0.004052</velocity>
          <acceleration>1.70149 2.59035 -2.26698 0.837807 -1.38748 1.82726</acceleration>
          <wrench>12.6246 19.2197 -16.8204 0 -0 0</wrench>
        </link>
        <link name='lbwheel_1'>
          <pose>2.16915 -1.1065 0.089952 3.14034 -0.100691 -0.065534</pose>
          <velocity>-0.000174 -0.000781 0.003748 -0.040939 0.006882 -0.004031</velocity>
          <acceleration>-0.910859 0.268844 0.752734 1.37748 0.24239 1.59228</acceleration>
          <wrench>-1.86254 0.549738 1.5392 0 -0 0</wrench>
        </link>
        <link name='lfwheel_1'>
          <pose>2.01947 -1.09666 0.089679 3.1399 -0.799623 -0.06445</pose>
          <velocity>-1.1e-05 -0.00037 0.004216 -0.055227 -0.000687 -0.00438</velocity>
          <acceleration>-0.675519 0.451323 9.95578 -1.75381 1.23887 -0.877303</acceleration>
          <wrench>-1.38131 0.922873 20.3578 0 -0 0</wrench>
        </link>
        <link name='rbwheel_1'>
          <pose>2.18358 -0.886973 0.08968 3.14029 -0.267488 -0.065315</pose>
          <velocity>0.000719 -0.00081 -0.005764 -0.038186 0.00657 -0.004061</velocity>
          <acceleration>-0.423643 0.276545 -16.0317 0.641858 0.518603 -2.05036</acceleration>
          <wrench>-0.866273 0.565485 -32.782 0 -0 0</wrench>
        </link>
        <link name='rfwheel_1'>
          <pose>2.0339 -0.877131 0.089406 3.13297 1.4264 -0.074189</pose>
          <velocity>0.000779 -0.000264 -0.005099 -0.041843 0.006824 -0.003888</velocity>
          <acceleration>-0.423486 0.477147 -6.84533 -2.03903 -1.057 2.18163</acceleration>
          <wrench>-0.865952 0.975681 -13.9975 0 -0 0</wrench>
        </link>
      </model>
      <model name='ground_plane'>
        <pose>0 0 0 0 -0 0</pose>
        <scale>1 1 1</scale>
        <link name='link'>
          <pose>0 0 0 0 -0 0</pose>
          <velocity>0 0 0 0 -0 0</velocity>
          <acceleration>0 0 0 0 -0 0</acceleration>
          <wrench>0 0 0 0 -0 0</wrench>
        </link>
      </model>
      <model name='line_track'>
        <pose>-2.86298 2.05919 0 0 -0 0</pose>
        <scale>1 1 1</scale>
        <link name='link_0'>
          <pose>-2.01434 2.01015 0 0 -0 0</pose>
          <velocity>0 0 0 0 -0 0</velocity>
          <acceleration>0 0 0 0 -0 0</acceleration>
          <wrench>0 0 0 0 -0 0</wrench>
        </link>
        <link name='link_1'>
          <pose>-3.71162 2.10823 -0.029 0 -0 0</pose>
          <velocity>0 0 0 0 -0 0</velocity>
          <acceleration>0 0 0 0 -0 0</acceleration>
          <wrench>0 0 0 0 -0 0</wrench>
        </link>
      </model>
      <light name='sun'>
        <pose>0 0 10 0 -0 0</pose>
      </light>
    </state>
    <gui fullscreen='0'>
      <camera name='user_camera'>
        <pose>-2.18429 -1.27693 5.8064 -0 0.943643 0.076188</pose>
        <view_controller>orbit</view_controller>
        <projection_type>perspective</projection_type>
      </camera>
    </gui>
    <model name='bal_robot_urdf'>
      <link name='base_link'>
        <inertial>
          <pose>0.045593 0.001215 0.090924 0 -0 0</pose>
          <mass>7.41975</mass>
          <inertia>
            <ixx>0.0333575</ixx>
            <ixy>-4.40071e-06</ixy>
            <ixz>-0.00569166</ixz>
            <iyy>0.0671669</iyy>
            <iyz>1.21234e-06</iyz>
            <izz>0.0773116</izz>
          </inertia>
        </inertial>
        <collision name='base_link_collision'>
          <pose>0 0 0 0 -0 0</pose>
          <geometry>
            <mesh>
              <scale>0.001 0.001 0.001</scale>
              <uri>file:///home/abcom/Documents/GitHub/assignment_ws/install/bal_robot_urdf_description/share/bal_robot_urdf_description/meshes/base_link.stl</uri>
            </mesh>
          </geometry>
          <surface>
            <contact>
              <ode/>
            </contact>
            <friction>
              <ode>
                <mu>0.2</mu>
                <mu2>0.2</mu2>
              </ode>
              <torsional>
                <ode/>
              </torsional>
            </friction>
            <bounce/>
          </surface>
          <max_contacts>10</max_contacts>
        </collision>
        <collision name='base_link_fixed_joint_lump__gps_1_collision_1'>
          <pose>0 0 0 0 -0 0</pose>
          <geometry>
            <mesh>
              <scale>0.001 0.001 0.001</scale>
              <uri>file:///home/abcom/Documents/GitHub/assignment_ws/install/bal_robot_urdf_description/share/bal_robot_urdf_description/meshes/gps_1.stl</uri>
            </mesh>
          </geometry>
          <surface>
            <contact>
              <ode/>
            </contact>
            <friction>
              <ode>
                <mu>0.2</mu>
                <mu2>0.2</mu2>
              </ode>
              <torsional>
                <ode/>
              </torsional>
            </friction>
            <bounce/>
          </surface>
          <max_contacts>10</max_contacts>
        </collision>
        <collision name='base_link_fixed_joint_lump__lidar_1_collision_2'>
          <pose>0 0 0 0 -0 0</pose>
          <geometry>
            <mesh>
              <scale>0.001 0.001 0.001</scale>
              <uri>file:///home/abcom/Documents/GitHub/assignment_ws/install/bal_robot_urdf_description/share/bal_robot_urdf_description/meshes/lidar_1.stl</uri>
            </mesh>
          </geometry>
          <surface>
            <contact>
              <ode/>
            </contact>
            <friction>
              <ode>
                <mu>0.2</mu>
                <mu2>0.2</mu2>
              </ode>
              <torsional>
                <ode/>
              </torsional>
            </friction>
            <bounce/>
          </surface>
          <max_contacts>10</max_contacts>
        </collision>
        <collision name='base_link_fixed_joint_lump__realsence_1_collision_3'>
          <pose>-0.2 0 0 0 -0 0</pose>
          <geometry>
            <mesh>
              <scale>0.001 0.001 0.001</scale>
              <uri>file:///home/abcom/Documents/GitHub/assignment_ws/install/bal_robot_urdf_description/share/bal_robot_urdf_description/meshes/realsence_1.stl</uri>
            </mesh>
          </geometry>
          <surface>
            <contact>
              <ode/>
            </contact>
            <friction>
              <ode>
                <mu>0.2</mu>
                <mu2>0.2</mu2>
              </ode>
              <torsional>
                <ode/>
              </torsional>
            </friction>
            <bounce/>
          </surface>
          <max_contacts>10</max_contacts>
        </collision>
        <collision name='base_link_fixed_joint_lump__imu_1_collision_4'>
          <pose>0 0 0 0 -0 0</pose>
          <geometry>
            <mesh>
              <scale>0.001 0.001 0.001</scale>
              <uri>file:///home/abcom/Documents/GitHub/assignment_ws/install/bal_robot_urdf_description/share/bal_robot_urdf_description/meshes/imu_1.stl</uri>
            </mesh>
          </geometry>
          <surface>
            <contact>
              <ode/>
            </contact>
            <friction>
              <ode>
                <mu>0.2</mu>
                <mu2>0.2</mu2>
              </ode>
              <torsional>
                <ode/>
              </torsional>
            </friction>
            <bounce/>
          </surface>
          <max_contacts>10</max_contacts>
        </collision>
        <visual name='base_link_visual'>
          <pose>0 0 0 0 -0 0</pose>
          <geometry>
            <mesh>
              <scale>0.001 0.001 0.001</scale>
              <uri>file:///home/abcom/Documents/GitHub/assignment_ws/install/bal_robot_urdf_description/share/bal_robot_urdf_description/meshes/base_link.stl</uri>
            </mesh>
          </geometry>
          <material>
            <script>
              <name>Gazebo/Silver</name>
              <uri>file://media/materials/scripts/gazebo.material</uri>
            </script>
          </material>
        </visual>
        <visual name='base_link_fixed_joint_lump__gps_1_visual_1'>
          <pose>0 0 0 0 -0 0</pose>
          <geometry>
            <mesh>
              <scale>0.001 0.001 0.001</scale>
              <uri>file:///home/abcom/Documents/GitHub/assignment_ws/install/bal_robot_urdf_description/share/bal_robot_urdf_description/meshes/gps_1.stl</uri>
            </mesh>
          </geometry>
          <material>
            <script>
              <name>Gazebo/Silver</name>
              <uri>file://media/materials/scripts/gazebo.material</uri>
            </script>
          </material>
        </visual>
        <visual name='base_link_fixed_joint_lump__lidar_1_visual_2'>
          <pose>0 0 0 0 -0 0</pose>
          <geometry>
            <mesh>
              <scale>0.001 0.001 0.001</scale>
              <uri>file:///home/abcom/Documents/GitHub/assignment_ws/install/bal_robot_urdf_description/share/bal_robot_urdf_description/meshes/lidar_1.stl</uri>
            </mesh>
          </geometry>
          <material>
            <script>
              <name>Gazebo/Silver</name>
              <uri>file://media/materials/scripts/gazebo.material</uri>
            </script>
          </material>
        </visual>
        <visual name='base_link_fixed_joint_lump__realsence_1_visual_3'>
          <pose>-0.2 0 0 0 -0 0</pose>
          <geometry>
            <mesh>
              <scale>0.001 0.001 0.001</scale>
              <uri>file:///home/abcom/Documents/GitHub/assignment_ws/install/bal_robot_urdf_description/share/bal_robot_urdf_description/meshes/realsence_1.stl</uri>
            </mesh>
          </geometry>
          <material>
            <script>
              <name>Gazebo/Silver</name>
              <uri>file://media/materials/scripts/gazebo.material</uri>
            </script>
          </material>
        </visual>
        <visual name='base_link_fixed_joint_lump__imu_1_visual_4'>
          <pose>0 0 0 0 -0 0</pose>
          <geometry>
            <mesh>
              <scale>0.001 0.001 0.001</scale>
              <uri>file:///home/abcom/Documents/GitHub/assignment_ws/install/bal_robot_urdf_description/share/bal_robot_urdf_description/meshes/imu_1.stl</uri>
            </mesh>
          </geometry>
          <material>
            <script>
              <name>Gazebo/Silver</name>
              <uri>file://media/materials/scripts/gazebo.material</uri>
            </script>
          </material>
        </visual>
        <self_collide>1</self_collide>
        <gravity>1</gravity>
        <self_collide>1</self_collide>
        <self_collide>1</self_collide>
        <sensor name='lidar_sensor' type='ray'>
          <visualize>1</visualize>
          <update_rate>10</update_rate>
          <ray>
            <scan>
              <horizontal>
                <samples>360</samples>
                <resolution>1</resolution>
                <min_angle>-3.14</min_angle>
                <max_angle>3.14</max_angle>
              </horizontal>
              <vertical>
                <samples>1</samples>
                <min_angle>0</min_angle>
                <max_angle>0</max_angle>
              </vertical>
            </scan>
            <range>
              <min>0.3</min>
              <max>10</max>
              <resolution>0.01</resolution>
            </range>
            <noise>
              <type>gaussian</type>
              <mean>0</mean>
              <stddev>0.01</stddev>
            </noise>
          </ray>
          <plugin name='laser_controller' filename='libgazebo_ros_ray_sensor.so'>
            <ros>
              <argument>~/out:=scan</argument>
            </ros>
            <output_type>sensor_msgs/LaserScan</output_type>
            <frame_name>lidar_1</frame_name>
          </plugin>
          <pose>0.117737 0.001226 0.164764 0 -0 0</pose>
        </sensor>
        <self_collide>1</self_collide>
        <sensor name='camera' type='camera'>
          <visualize>1</visualize>
          <update_rate>10</update_rate>
          <camera>
            <horizontal_fov>1.089</horizontal_fov>
            <image>
              <format>R8G8B8</format>
              <width>640</width>
              <height>480</height>
            </image>
            <clip>
              <near>0.05</near>
              <far>12</far>
            </clip>
          </camera>
          <plugin name='camera_controller' filename='libgazebo_ros_camera.so'>
            <frame_name>realsence_1_optical</frame_name>
          </plugin>
          <pose>0.187737 0.001226 0.082264 0 -0 0</pose>
        </sensor>
        <self_collide>1</self_collide>
        <gravity>1</gravity>
        <sensor name='imu_sensor' type='imu'>
          <always_on>1</always_on>
          <update_rate>100</update_rate>
          <visualize>1</visualize>
          <topic>__default_topic__</topic>
          <plugin name='imu_data' filename='libgazebo_ros_imu_sensor.so'>
            <topicName>imu</topicName>
            <bodyName>imu_1</bodyName>
            <updateRateHZ>10.0</updateRateHZ>
            <gaussianNoise>0.0</gaussianNoise>
            <xyzOffset>0 0 0</xyzOffset>
            <rpyOffset>0 0 0</rpyOffset>
            <frameName>imu_1</frameName>
            <initialOrientationAsReference>0</initialOrientationAsReference>
          </plugin>
          <pose>-0.005 0 0.099764 0 -0 0</pose>
          <imu/>
        </sensor>
        <enable_wind>0</enable_wind>
        <kinematic>0</kinematic>
      </link>
      <joint name='Revolute 4' type='revolute'>
        <pose relative_to='base_link'>0.107737 -0.108774 0.054764 0 -0 0</pose>
        <parent>base_link</parent>
        <child>rfwheel_1</child>
        <axis>
          <xyz>0 1 0</xyz>
          <limit>
            <lower>-1e+16</lower>
            <upper>1e+16</upper>
          </limit>
          <dynamics>
            <spring_reference>0</spring_reference>
            <spring_stiffness>0</spring_stiffness>
          </dynamics>
        </axis>
      </joint>
      <link name='rfwheel_1'>
        <pose relative_to='Revolute 4'>0 0 0 0 -0 0</pose>
        <inertial>
          <pose>-0.000489 -0.015 0.000114 0 -0 0</pose>
          <mass>2.04482</mass>
          <inertia>
            <ixx>0.001605</ixx>
            <ixy>0</ixy>
            <ixz>2e-06</ixz>
            <iyy>0.002914</iyy>
            <iyz>0</iyz>
            <izz>0.001615</izz>
          </inertia>
        </inertial>
        <collision name='rfwheel_1_collision'>
          <pose>-0.107737 0.108774 -0.054764 0 -0 0</pose>
          <geometry>
            <mesh>
              <scale>0.001 0.001 0.001</scale>
              <uri>file:///home/abcom/Documents/GitHub/assignment_ws/install/bal_robot_urdf_description/share/bal_robot_urdf_description/meshes/rfwheel_1.stl</uri>
            </mesh>
          </geometry>
          <surface>
            <contact>
              <ode/>
            </contact>
            <friction>
              <ode>
                <mu>0.2</mu>
                <mu2>0.2</mu2>
              </ode>
              <torsional>
                <ode/>
              </torsional>
            </friction>
            <bounce/>
          </surface>
          <max_contacts>10</max_contacts>
        </collision>
        <visual name='rfwheel_1_visual'>
          <pose>-0.107737 0.108774 -0.054764 0 -0 0</pose>
          <geometry>
            <mesh>
              <scale>0.001 0.001 0.001</scale>
              <uri>file:///home/abcom/Documents/GitHub/assignment_ws/install/bal_robot_urdf_description/share/bal_robot_urdf_description/meshes/rfwheel_1.stl</uri>
            </mesh>
          </geometry>
          <material>
            <script>
              <name>Gazebo/Silver</name>
              <uri>file://media/materials/scripts/gazebo.material</uri>
            </script>
          </material>
        </visual>
        <self_collide>1</self_collide>
        <enable_wind>0</enable_wind>
        <kinematic>0</kinematic>
      </link>
      <joint name='Revolute 5' type='revolute'>
        <pose relative_to='base_link'>-0.042263 -0.108774 0.054764 0 -0 0</pose>
        <parent>base_link</parent>
        <child>rbwheel_1</child>
        <axis>
          <xyz>0 1 0</xyz>
          <limit>
            <lower>-1e+16</lower>
            <upper>1e+16</upper>
          </limit>
          <dynamics>
            <spring_reference>0</spring_reference>
            <spring_stiffness>0</spring_stiffness>
          </dynamics>
        </axis>
      </joint>
      <link name='rbwheel_1'>
        <pose relative_to='Revolute 5'>0 0 0 0 -0 0</pose>
        <inertial>
          <pose>-0.000489 -0.015 0.000114 0 -0 0</pose>
          <mass>2.04482</mass>
          <inertia>
            <ixx>0.001605</ixx>
            <ixy>0</ixy>
            <ixz>2e-06</ixz>
            <iyy>0.002914</iyy>
            <iyz>0</iyz>
            <izz>0.001615</izz>
          </inertia>
        </inertial>
        <collision name='rbwheel_1_collision'>
          <pose>0.042263 0.108774 -0.054764 0 -0 0</pose>
          <geometry>
            <mesh>
              <scale>0.001 0.001 0.001</scale>
              <uri>file:///home/abcom/Documents/GitHub/assignment_ws/install/bal_robot_urdf_description/share/bal_robot_urdf_description/meshes/rbwheel_1.stl</uri>
            </mesh>
          </geometry>
          <surface>
            <contact>
              <ode/>
            </contact>
            <friction>
              <ode>
                <mu>0.2</mu>
                <mu2>0.2</mu2>
              </ode>
              <torsional>
                <ode/>
              </torsional>
            </friction>
            <bounce/>
          </surface>
          <max_contacts>10</max_contacts>
        </collision>
        <visual name='rbwheel_1_visual'>
          <pose>0.042263 0.108774 -0.054764 0 -0 0</pose>
          <geometry>
            <mesh>
              <scale>0.001 0.001 0.001</scale>
              <uri>file:///home/abcom/Documents/GitHub/assignment_ws/install/bal_robot_urdf_description/share/bal_robot_urdf_description/meshes/rbwheel_1.stl</uri>
            </mesh>
          </geometry>
          <material>
            <script>
              <name>Gazebo/Silver</name>
              <uri>file://media/materials/scripts/gazebo.material</uri>
            </script>
          </material>
        </visual>
        <self_collide>1</self_collide>
        <enable_wind>0</enable_wind>
        <kinematic>0</kinematic>
      </link>
      <joint name='Revolute 6' type='revolute'>
        <pose relative_to='base_link'>0.107737 0.111226 0.054764 0 -0 0</pose>
        <parent>base_link</parent>
        <child>lfwheel_1</child>
        <axis>
          <xyz>0 1 0</xyz>
          <limit>
            <lower>-1e+16</lower>
            <upper>1e+16</upper>
          </limit>
          <dynamics>
            <spring_reference>0</spring_reference>
            <spring_stiffness>0</spring_stiffness>
          </dynamics>
        </axis>
      </joint>
      <link name='lfwheel_1'>
        <pose relative_to='Revolute 6'>0 0 0 0 -0 0</pose>
        <inertial>
          <pose>-0.000489 0.015 0.000114 0 -0 0</pose>
          <mass>2.04482</mass>
          <inertia>
            <ixx>0.001605</ixx>
            <ixy>0</ixy>
            <ixz>2e-06</ixz>
            <iyy>0.002914</iyy>
            <iyz>0</iyz>
            <izz>0.001615</izz>
          </inertia>
        </inertial>
        <collision name='lfwheel_1_collision'>
          <pose>-0.107737 -0.111226 -0.054764 0 -0 0</pose>
          <geometry>
            <mesh>
              <scale>0.001 0.001 0.001</scale>
              <uri>file:///home/abcom/Documents/GitHub/assignment_ws/install/bal_robot_urdf_description/share/bal_robot_urdf_description/meshes/lfwheel_1.stl</uri>
            </mesh>
          </geometry>
          <surface>
            <contact>
              <ode/>
            </contact>
            <friction>
              <ode>
                <mu>0.2</mu>
                <mu2>0.2</mu2>
              </ode>
              <torsional>
                <ode/>
              </torsional>
            </friction>
            <bounce/>
          </surface>
          <max_contacts>10</max_contacts>
        </collision>
        <visual name='lfwheel_1_visual'>
          <pose>-0.107737 -0.111226 -0.054764 0 -0 0</pose>
          <geometry>
            <mesh>
              <scale>0.001 0.001 0.001</scale>
              <uri>file:///home/abcom/Documents/GitHub/assignment_ws/install/bal_robot_urdf_description/share/bal_robot_urdf_description/meshes/lfwheel_1.stl</uri>
            </mesh>
          </geometry>
          <material>
            <script>
              <name>Gazebo/Silver</name>
              <uri>file://media/materials/scripts/gazebo.material</uri>
            </script>
          </material>
        </visual>
        <self_collide>1</self_collide>
        <enable_wind>0</enable_wind>
        <kinematic>0</kinematic>
      </link>
      <joint name='Revolute 7' type='revolute'>
        <pose relative_to='base_link'>-0.042263 0.111226 0.054764 0 -0 0</pose>
        <parent>base_link</parent>
        <child>lbwheel_1</child>
        <axis>
          <xyz>0 1 0</xyz>
          <limit>
            <lower>-1e+16</lower>
            <upper>1e+16</upper>
          </limit>
          <dynamics>
            <spring_reference>0</spring_reference>
            <spring_stiffness>0</spring_stiffness>
          </dynamics>
        </axis>
      </joint>
      <link name='lbwheel_1'>
        <pose relative_to='Revolute 7'>0 0 0 0 -0 0</pose>
        <inertial>
          <pose>-0.000489 0.015 0.000114 0 -0 0</pose>
          <mass>2.04482</mass>
          <inertia>
            <ixx>0.001605</ixx>
            <ixy>0</ixy>
            <ixz>2e-06</ixz>
            <iyy>0.002914</iyy>
            <iyz>0</iyz>
            <izz>0.001615</izz>
          </inertia>
        </inertial>
        <collision name='lbwheel_1_collision'>
          <pose>0.042263 -0.111226 -0.054764 0 -0 0</pose>
          <geometry>
            <mesh>
              <scale>0.001 0.001 0.001</scale>
              <uri>file:///home/abcom/Documents/GitHub/assignment_ws/install/bal_robot_urdf_description/share/bal_robot_urdf_description/meshes/lbwheel_1.stl</uri>
            </mesh>
          </geometry>
          <surface>
            <contact>
              <ode/>
            </contact>
            <friction>
              <ode>
                <mu>0.2</mu>
                <mu2>0.2</mu2>
              </ode>
              <torsional>
                <ode/>
              </torsional>
            </friction>
            <bounce/>
          </surface>
          <max_contacts>10</max_contacts>
        </collision>
        <visual name='lbwheel_1_visual'>
          <pose>0.042263 -0.111226 -0.054764 0 -0 0</pose>
          <geometry>
            <mesh>
              <scale>0.001 0.001 0.001</scale>
              <uri>file:///home/abcom/Documents/GitHub/assignment_ws/install/bal_robot_urdf_description/share/bal_robot_urdf_description/meshes/lbwheel_1.stl</uri>
            </mesh>
          </geometry>
          <material>
            <script>
              <name>Gazebo/Silver</name>
              <uri>file://media/materials/scripts/gazebo.material</uri>
            </script>
          </material>
        </visual>
        <self_collide>1</self_collide>
        <enable_wind>0</enable_wind>
        <kinematic>0</kinematic>
      </link>
      <plugin name='control' filename='libgazebo_ros_control.so'/>
      <plugin name='front_diff_drive' filename='libgazebo_ros_diff_drive.so'>
        <ros/>
        <update_rate>30</update_rate>
        <left_joint>Revolute 6</left_joint>
        <right_joint>Revolute 4</right_joint>
        <wheel_separation>0.22</wheel_separation>
        <wheel_diameter>0.05</wheel_diameter>
        <robot_base_frame>base_link</robot_base_frame>
        <max_wheel_torque>0.5</max_wheel_torque>
        <max_wheel_acceleration>0.5</max_wheel_acceleration>
        <command_topic>cmd_vel</command_topic>
        <odometry_topic>odom</odometry_topic>
        <odometry_frame>odom</odometry_frame>
        <robot_base_frame>base_link</robot_base_frame>
        <publish_odom>1</publish_odom>
        <publish_odom_tf>1</publish_odom_tf>
        <publish_wheel_tf>1</publish_wheel_tf>
      </plugin>
      <static>0</static>
      <plugin name='rear_diff_drive' filename='libgazebo_ros_diff_drive.so'>
        <ros/>
        <update_rate>30</update_rate>
        <left_joint>Revolute 7</left_joint>
        <right_joint>Revolute 5</right_joint>
        <wheel_separation>0.22</wheel_separation>
        <wheel_diameter>0.05</wheel_diameter>
        <robot_base_frame>base_link</robot_base_frame>
        <max_wheel_torque>0.5</max_wheel_torque>
        <max_wheel_acceleration>0.5</max_wheel_acceleration>
        <command_topic>cmd_vel</command_topic>
        <odometry_topic>odom</odometry_topic>
        <odometry_frame>odom</odometry_frame>
        <robot_base_frame>base_link</robot_base_frame>
        <publish_odom>1</publish_odom>
        <publish_odom_tf>1</publish_odom_tf>
        <publish_wheel_tf>1</publish_wheel_tf>
      </plugin>
      <pose>0 0 0 0 -0 0</pose>
    </model>
  </world>
</sdf>
